{
 "cells": [
  {
   "cell_type": "code",
   "execution_count": 2,
   "metadata": {},
   "outputs": [
    {
     "name": "stdout",
     "output_type": "stream",
     "text": [
      "Requirement already satisfied: openCV-python in c:\\users\\sarth\\.conda\\envs\\tensorflow\\lib\\site-packages (4.7.0.72)\n",
      "Requirement already satisfied: numpy>=1.17.3 in c:\\users\\sarth\\.conda\\envs\\tensorflow\\lib\\site-packages (from openCV-python) (1.24.3)\n",
      "Note: you may need to restart the kernel to use updated packages.\n",
      "Note: you may need to restart the kernel to use updated packages.\n"
     ]
    },
    {
     "name": "stderr",
     "output_type": "stream",
     "text": [
      "ERROR: Could not find a version that satisfies the requirement python (from versions: none)\n",
      "ERROR: No matching distribution found for python\n"
     ]
    },
    {
     "name": "stdout",
     "output_type": "stream",
     "text": [
      "^C\n",
      "Note: you may need to restart the kernel to use updated packages.\n"
     ]
    }
   ],
   "source": [
    "%pip install openCV-python\n",
    "%pip install python\n",
    "%pip install tensorflow"
   ]
  },
  {
   "cell_type": "code",
   "execution_count": null,
   "metadata": {},
   "outputs": [
    {
     "name": "stdout",
     "output_type": "stream",
     "text": [
      "Collecting tensorflow\n",
      "  Using cached tensorflow-2.12.0-cp310-cp310-win_amd64.whl (1.9 kB)\n",
      "Collecting tensorflow-intel==2.12.0\n",
      "  Downloading tensorflow_intel-2.12.0-cp310-cp310-win_amd64.whl (272.8 MB)\n",
      "                                              4.8/272.8 MB ? eta -:--:--\n",
      "Note: you may need to restart the kernel to use updated packages.\n"
     ]
    },
    {
     "name": "stderr",
     "output_type": "stream",
     "text": [
      "ERROR: Exception:\n",
      "Traceback (most recent call last):\n",
      "  File \"c:\\Users\\sarth\\.conda\\envs\\tensorflow\\lib\\site-packages\\pip\\_vendor\\urllib3\\response.py\", line 437, in _error_catcher\n",
      "    yield\n",
      "  File \"c:\\Users\\sarth\\.conda\\envs\\tensorflow\\lib\\site-packages\\pip\\_vendor\\urllib3\\response.py\", line 560, in read\n",
      "    data = self._fp_read(amt) if not fp_closed else b\"\"\n",
      "  File \"c:\\Users\\sarth\\.conda\\envs\\tensorflow\\lib\\site-packages\\pip\\_vendor\\urllib3\\response.py\", line 526, in _fp_read\n",
      "    return self._fp.read(amt) if amt is not None else self._fp.read()\n",
      "  File \"c:\\Users\\sarth\\.conda\\envs\\tensorflow\\lib\\site-packages\\pip\\_vendor\\cachecontrol\\filewrapper.py\", line 90, in read\n",
      "    data = self.__fp.read(amt)\n",
      "  File \"c:\\Users\\sarth\\.conda\\envs\\tensorflow\\lib\\http\\client.py\", line 465, in read\n",
      "    s = self.fp.read(amt)\n",
      "  File \"c:\\Users\\sarth\\.conda\\envs\\tensorflow\\lib\\socket.py\", line 705, in readinto\n",
      "    return self._sock.recv_into(b)\n",
      "  File \"c:\\Users\\sarth\\.conda\\envs\\tensorflow\\lib\\ssl.py\", line 1274, in recv_into\n",
      "    return self.read(nbytes, buffer)\n",
      "  File \"c:\\Users\\sarth\\.conda\\envs\\tensorflow\\lib\\ssl.py\", line 1130, in read\n",
      "    return self._sslobj.read(len, buffer)\n",
      "TimeoutError: The read operation timed out\n",
      "\n",
      "During handling of the above exception, another exception occurred:\n",
      "\n",
      "Traceback (most recent call last):\n",
      "  File \"c:\\Users\\sarth\\.conda\\envs\\tensorflow\\lib\\site-packages\\pip\\_internal\\cli\\base_command.py\", line 160, in exc_logging_wrapper\n",
      "    status = run_func(*args)\n",
      "  File \"c:\\Users\\sarth\\.conda\\envs\\tensorflow\\lib\\site-packages\\pip\\_internal\\cli\\req_command.py\", line 247, in wrapper\n",
      "    return func(self, options, args)\n",
      "  File \"c:\\Users\\sarth\\.conda\\envs\\tensorflow\\lib\\site-packages\\pip\\_internal\\commands\\install.py\", line 400, in run\n",
      "    requirement_set = resolver.resolve(\n",
      "  File \"c:\\Users\\sarth\\.conda\\envs\\tensorflow\\lib\\site-packages\\pip\\_internal\\resolution\\resolvelib\\resolver.py\", line 92, in resolve\n",
      "    result = self._result = resolver.resolve(\n",
      "  File \"c:\\Users\\sarth\\.conda\\envs\\tensorflow\\lib\\site-packages\\pip\\_vendor\\resolvelib\\resolvers.py\", line 481, in resolve\n",
      "    state = resolution.resolve(requirements, max_rounds=max_rounds)\n",
      "  File \"c:\\Users\\sarth\\.conda\\envs\\tensorflow\\lib\\site-packages\\pip\\_vendor\\resolvelib\\resolvers.py\", line 373, in resolve\n",
      "    failure_causes = self._attempt_to_pin_criterion(name)\n",
      "  File \"c:\\Users\\sarth\\.conda\\envs\\tensorflow\\lib\\site-packages\\pip\\_vendor\\resolvelib\\resolvers.py\", line 213, in _attempt_to_pin_criterion\n",
      "    criteria = self._get_updated_criteria(candidate)\n",
      "  File \"c:\\Users\\sarth\\.conda\\envs\\tensorflow\\lib\\site-packages\\pip\\_vendor\\resolvelib\\resolvers.py\", line 204, in _get_updated_criteria\n",
      "    self._add_to_criteria(criteria, requirement, parent=candidate)\n",
      "  File \"c:\\Users\\sarth\\.conda\\envs\\tensorflow\\lib\\site-packages\\pip\\_vendor\\resolvelib\\resolvers.py\", line 172, in _add_to_criteria\n",
      "    if not criterion.candidates:\n",
      "  File \"c:\\Users\\sarth\\.conda\\envs\\tensorflow\\lib\\site-packages\\pip\\_vendor\\resolvelib\\structs.py\", line 151, in __bool__\n",
      "    return bool(self._sequence)\n",
      "  File \"c:\\Users\\sarth\\.conda\\envs\\tensorflow\\lib\\site-packages\\pip\\_internal\\resolution\\resolvelib\\found_candidates.py\", line 155, in __bool__\n",
      "    return any(self)\n",
      "  File \"c:\\Users\\sarth\\.conda\\envs\\tensorflow\\lib\\site-packages\\pip\\_internal\\resolution\\resolvelib\\found_candidates.py\", line 143, in <genexpr>\n",
      "    return (c for c in iterator if id(c) not in self._incompatible_ids)\n",
      "  File \"c:\\Users\\sarth\\.conda\\envs\\tensorflow\\lib\\site-packages\\pip\\_internal\\resolution\\resolvelib\\found_candidates.py\", line 47, in _iter_built\n",
      "    candidate = func()\n",
      "  File \"c:\\Users\\sarth\\.conda\\envs\\tensorflow\\lib\\site-packages\\pip\\_internal\\resolution\\resolvelib\\factory.py\", line 206, in _make_candidate_from_link\n",
      "    self._link_candidate_cache[link] = LinkCandidate(\n",
      "  File \"c:\\Users\\sarth\\.conda\\envs\\tensorflow\\lib\\site-packages\\pip\\_internal\\resolution\\resolvelib\\candidates.py\", line 297, in __init__\n",
      "    super().__init__(\n",
      "  File \"c:\\Users\\sarth\\.conda\\envs\\tensorflow\\lib\\site-packages\\pip\\_internal\\resolution\\resolvelib\\candidates.py\", line 162, in __init__\n",
      "    self.dist = self._prepare()\n",
      "  File \"c:\\Users\\sarth\\.conda\\envs\\tensorflow\\lib\\site-packages\\pip\\_internal\\resolution\\resolvelib\\candidates.py\", line 231, in _prepare\n",
      "    dist = self._prepare_distribution()\n",
      "  File \"c:\\Users\\sarth\\.conda\\envs\\tensorflow\\lib\\site-packages\\pip\\_internal\\resolution\\resolvelib\\candidates.py\", line 308, in _prepare_distribution\n",
      "    return preparer.prepare_linked_requirement(self._ireq, parallel_builds=True)\n",
      "  File \"c:\\Users\\sarth\\.conda\\envs\\tensorflow\\lib\\site-packages\\pip\\_internal\\operations\\prepare.py\", line 491, in prepare_linked_requirement\n",
      "    return self._prepare_linked_requirement(req, parallel_builds)\n",
      "  File \"c:\\Users\\sarth\\.conda\\envs\\tensorflow\\lib\\site-packages\\pip\\_internal\\operations\\prepare.py\", line 536, in _prepare_linked_requirement\n",
      "    local_file = unpack_url(\n",
      "  File \"c:\\Users\\sarth\\.conda\\envs\\tensorflow\\lib\\site-packages\\pip\\_internal\\operations\\prepare.py\", line 166, in unpack_url\n",
      "    file = get_http_url(\n",
      "  File \"c:\\Users\\sarth\\.conda\\envs\\tensorflow\\lib\\site-packages\\pip\\_internal\\operations\\prepare.py\", line 107, in get_http_url\n",
      "    from_path, content_type = download(link, temp_dir.path)\n",
      "  File \"c:\\Users\\sarth\\.conda\\envs\\tensorflow\\lib\\site-packages\\pip\\_internal\\network\\download.py\", line 147, in __call__\n",
      "    for chunk in chunks:\n",
      "  File \"c:\\Users\\sarth\\.conda\\envs\\tensorflow\\lib\\site-packages\\pip\\_internal\\cli\\progress_bars.py\", line 53, in _rich_progress_bar\n",
      "    for chunk in iterable:\n",
      "  File \"c:\\Users\\sarth\\.conda\\envs\\tensorflow\\lib\\site-packages\\pip\\_internal\\network\\utils.py\", line 63, in response_chunks\n",
      "    for chunk in response.raw.stream(\n",
      "  File \"c:\\Users\\sarth\\.conda\\envs\\tensorflow\\lib\\site-packages\\pip\\_vendor\\urllib3\\response.py\", line 621, in stream\n",
      "    data = self.read(amt=amt, decode_content=decode_content)\n",
      "  File \"c:\\Users\\sarth\\.conda\\envs\\tensorflow\\lib\\site-packages\\pip\\_vendor\\urllib3\\response.py\", line 559, in read\n",
      "    with self._error_catcher():\n",
      "  File \"c:\\Users\\sarth\\.conda\\envs\\tensorflow\\lib\\contextlib.py\", line 153, in __exit__\n",
      "    self.gen.throw(typ, value, traceback)\n",
      "  File \"c:\\Users\\sarth\\.conda\\envs\\tensorflow\\lib\\site-packages\\pip\\_vendor\\urllib3\\response.py\", line 442, in _error_catcher\n",
      "    raise ReadTimeoutError(self._pool, None, \"Read timed out.\")\n",
      "pip._vendor.urllib3.exceptions.ReadTimeoutError: HTTPSConnectionPool(host='files.pythonhosted.org', port=443): Read timed out.\n"
     ]
    },
    {
     "name": "stderr",
     "output_type": "stream",
     "text": [
      "ERROR: Exception:"
     ]
    },
    {
     "name": "stdout",
     "output_type": "stream",
     "text": [
      "Collecting tensorflow\n",
      "  Using cached tensorflow-2.12.0-cp310-cp310-win_amd64.whl (1.9 kB)\n",
      "Collecting tensorflow-intel==2.12.0\n",
      "  Downloading tensorflow_intel-2.12.0-cp310-cp310-win_amd64.whl (272.8 MB)\n",
      "     -----                                    38.5/272.8 MB ? eta -:--:--\n"
     ]
    },
    {
     "name": "stderr",
     "output_type": "stream",
     "text": [
      "\n",
      "Traceback (most recent call last):\n",
      "  File \"c:\\Users\\sarth\\.conda\\envs\\tensorflow\\lib\\site-packages\\pip\\_vendor\\urllib3\\response.py\", line 437, in _error_catcher\n",
      "    yield\n",
      "  File \"c:\\Users\\sarth\\.conda\\envs\\tensorflow\\lib\\site-packages\\pip\\_vendor\\urllib3\\response.py\", line 560, in read\n",
      "    data = self._fp_read(amt) if not fp_closed else b\"\"\n",
      "  File \"c:\\Users\\sarth\\.conda\\envs\\tensorflow\\lib\\site-packages\\pip\\_vendor\\urllib3\\response.py\", line 526, in _fp_read\n",
      "    return self._fp.read(amt) if amt is not None else self._fp.read()\n",
      "  File \"c:\\Users\\sarth\\.conda\\envs\\tensorflow\\lib\\site-packages\\pip\\_vendor\\cachecontrol\\filewrapper.py\", line 90, in read\n",
      "    data = self.__fp.read(amt)\n",
      "  File \"c:\\Users\\sarth\\.conda\\envs\\tensorflow\\lib\\http\\client.py\", line 465, in read\n",
      "    s = self.fp.read(amt)\n",
      "  File \"c:\\Users\\sarth\\.conda\\envs\\tensorflow\\lib\\socket.py\", line 705, in readinto\n",
      "    return self._sock.recv_into(b)\n",
      "  File \"c:\\Users\\sarth\\.conda\\envs\\tensorflow\\lib\\ssl.py\", line 1274, in recv_into\n",
      "    return self.read(nbytes, buffer)\n",
      "  File \"c:\\Users\\sarth\\.conda\\envs\\tensorflow\\lib\\ssl.py\", line 1130, in read\n",
      "    return self._sslobj.read(len, buffer)\n",
      "TimeoutError: The read operation timed out\n",
      "\n",
      "During handling of the above exception, another exception occurred:\n",
      "\n",
      "Traceback (most recent call last):\n",
      "  File \"c:\\Users\\sarth\\.conda\\envs\\tensorflow\\lib\\site-packages\\pip\\_internal\\cli\\base_command.py\", line 160, in exc_logging_wrapper\n",
      "    status = run_func(*args)\n",
      "  File \"c:\\Users\\sarth\\.conda\\envs\\tensorflow\\lib\\site-packages\\pip\\_internal\\cli\\req_command.py\", line 247, in wrapper\n",
      "    return func(self, options, args)\n",
      "  File \"c:\\Users\\sarth\\.conda\\envs\\tensorflow\\lib\\site-packages\\pip\\_internal\\commands\\install.py\", line 400, in run\n",
      "    requirement_set = resolver.resolve(\n",
      "  File \"c:\\Users\\sarth\\.conda\\envs\\tensorflow\\lib\\site-packages\\pip\\_internal\\resolution\\resolvelib\\resolver.py\", line 92, in resolve\n",
      "    result = self._result = resolver.resolve(\n",
      "  File \"c:\\Users\\sarth\\.conda\\envs\\tensorflow\\lib\\site-packages\\pip\\_vendor\\resolvelib\\resolvers.py\", line 481, in resolve\n",
      "    state = resolution.resolve(requirements, max_rounds=max_rounds)\n",
      "  File \"c:\\Users\\sarth\\.conda\\envs\\tensorflow\\lib\\site-packages\\pip\\_vendor\\resolvelib\\resolvers.py\", line 373, in resolve\n",
      "    failure_causes = self._attempt_to_pin_criterion(name)\n",
      "  File \"c:\\Users\\sarth\\.conda\\envs\\tensorflow\\lib\\site-packages\\pip\\_vendor\\resolvelib\\resolvers.py\", line 213, in _attempt_to_pin_criterion\n",
      "    criteria = self._get_updated_criteria(candidate)\n",
      "  File \"c:\\Users\\sarth\\.conda\\envs\\tensorflow\\lib\\site-packages\\pip\\_vendor\\resolvelib\\resolvers.py\", line 204, in _get_updated_criteria\n",
      "    self._add_to_criteria(criteria, requirement, parent=candidate)\n",
      "  File \"c:\\Users\\sarth\\.conda\\envs\\tensorflow\\lib\\site-packages\\pip\\_vendor\\resolvelib\\resolvers.py\", line 172, in _add_to_criteria\n",
      "    if not criterion.candidates:\n",
      "  File \"c:\\Users\\sarth\\.conda\\envs\\tensorflow\\lib\\site-packages\\pip\\_vendor\\resolvelib\\structs.py\", line 151, in __bool__\n",
      "    return bool(self._sequence)\n",
      "  File \"c:\\Users\\sarth\\.conda\\envs\\tensorflow\\lib\\site-packages\\pip\\_internal\\resolution\\resolvelib\\found_candidates.py\", line 155, in __bool__\n",
      "    return any(self)\n",
      "  File \"c:\\Users\\sarth\\.conda\\envs\\tensorflow\\lib\\site-packages\\pip\\_internal\\resolution\\resolvelib\\found_candidates.py\", line 143, in <genexpr>\n",
      "    return (c for c in iterator if id(c) not in self._incompatible_ids)\n",
      "  File \"c:\\Users\\sarth\\.conda\\envs\\tensorflow\\lib\\site-packages\\pip\\_internal\\resolution\\resolvelib\\found_candidates.py\", line 47, in _iter_built\n",
      "    candidate = func()\n",
      "  File \"c:\\Users\\sarth\\.conda\\envs\\tensorflow\\lib\\site-packages\\pip\\_internal\\resolution\\resolvelib\\factory.py\", line 206, in _make_candidate_from_link\n",
      "    self._link_candidate_cache[link] = LinkCandidate(\n",
      "  File \"c:\\Users\\sarth\\.conda\\envs\\tensorflow\\lib\\site-packages\\pip\\_internal\\resolution\\resolvelib\\candidates.py\", line 297, in __init__\n",
      "    super().__init__(\n",
      "  File \"c:\\Users\\sarth\\.conda\\envs\\tensorflow\\lib\\site-packages\\pip\\_internal\\resolution\\resolvelib\\candidates.py\", line 162, in __init__\n",
      "    self.dist = self._prepare()\n",
      "  File \"c:\\Users\\sarth\\.conda\\envs\\tensorflow\\lib\\site-packages\\pip\\_internal\\resolution\\resolvelib\\candidates.py\", line 231, in _prepare\n",
      "    dist = self._prepare_distribution()\n",
      "  File \"c:\\Users\\sarth\\.conda\\envs\\tensorflow\\lib\\site-packages\\pip\\_internal\\resolution\\resolvelib\\candidates.py\", line 308, in _prepare_distribution\n",
      "    return preparer.prepare_linked_requirement(self._ireq, parallel_builds=True)\n",
      "  File \"c:\\Users\\sarth\\.conda\\envs\\tensorflow\\lib\\site-packages\\pip\\_internal\\operations\\prepare.py\", line 491, in prepare_linked_requirement\n",
      "    return self._prepare_linked_requirement(req, parallel_builds)\n",
      "  File \"c:\\Users\\sarth\\.conda\\envs\\tensorflow\\lib\\site-packages\\pip\\_internal\\operations\\prepare.py\", line 536, in _prepare_linked_requirement\n",
      "    local_file = unpack_url(\n",
      "  File \"c:\\Users\\sarth\\.conda\\envs\\tensorflow\\lib\\site-packages\\pip\\_internal\\operations\\prepare.py\", line 166, in unpack_url\n",
      "    file = get_http_url(\n",
      "  File \"c:\\Users\\sarth\\.conda\\envs\\tensorflow\\lib\\site-packages\\pip\\_internal\\operations\\prepare.py\", line 107, in get_http_url\n",
      "    from_path, content_type = download(link, temp_dir.path)\n",
      "  File \"c:\\Users\\sarth\\.conda\\envs\\tensorflow\\lib\\site-packages\\pip\\_internal\\network\\download.py\", line 147, in __call__\n",
      "    for chunk in chunks:\n",
      "  File \"c:\\Users\\sarth\\.conda\\envs\\tensorflow\\lib\\site-packages\\pip\\_internal\\cli\\progress_bars.py\", line 53, in _rich_progress_bar\n",
      "    for chunk in iterable:\n",
      "  File \"c:\\Users\\sarth\\.conda\\envs\\tensorflow\\lib\\site-packages\\pip\\_internal\\network\\utils.py\", line 63, in response_chunks\n",
      "    for chunk in response.raw.stream(\n",
      "  File \"c:\\Users\\sarth\\.conda\\envs\\tensorflow\\lib\\site-packages\\pip\\_vendor\\urllib3\\response.py\", line 621, in stream\n",
      "    data = self.read(amt=amt, decode_content=decode_content)\n",
      "  File \"c:\\Users\\sarth\\.conda\\envs\\tensorflow\\lib\\site-packages\\pip\\_vendor\\urllib3\\response.py\", line 559, in read\n",
      "    with self._error_catcher():\n",
      "  File \"c:\\Users\\sarth\\.conda\\envs\\tensorflow\\lib\\contextlib.py\", line 153, in __exit__\n",
      "    self.gen.throw(typ, value, traceback)\n",
      "  File \"c:\\Users\\sarth\\.conda\\envs\\tensorflow\\lib\\site-packages\\pip\\_vendor\\urllib3\\response.py\", line 442, in _error_catcher\n",
      "    raise ReadTimeoutError(self._pool, None, \"Read timed out.\")\n",
      "pip._vendor.urllib3.exceptions.ReadTimeoutError: HTTPSConnectionPool(host='files.pythonhosted.org', port=443): Read timed out.\n",
      "ERROR: Exception:\n",
      "Traceback (most recent call last):\n",
      "  File \"c:\\Users\\sarth\\.conda\\envs\\tensorflow\\lib\\site-packages\\pip\\_vendor\\urllib3\\response.py\", line 437, in _error_catcher\n",
      "    yield\n",
      "  File \"c:\\Users\\sarth\\.conda\\envs\\tensorflow\\lib\\site-packages\\pip\\_vendor\\urllib3\\response.py\", line 560, in read\n",
      "    data = self._fp_read(amt) if not fp_closed else b\"\"\n",
      "  File \"c:\\Users\\sarth\\.conda\\envs\\tensorflow\\lib\\site-packages\\pip\\_vendor\\urllib3\\response.py\", line 526, in _fp_read\n",
      "    return self._fp.read(amt) if amt is not None else self._fp.read()\n",
      "  File \"c:\\Users\\sarth\\.conda\\envs\\tensorflow\\lib\\site-packages\\pip\\_vendor\\cachecontrol\\filewrapper.py\", line 90, in read\n",
      "    data = self.__fp.read(amt)\n",
      "  File \"c:\\Users\\sarth\\.conda\\envs\\tensorflow\\lib\\http\\client.py\", line 465, in read\n",
      "    s = self.fp.read(amt)\n",
      "  File \"c:\\Users\\sarth\\.conda\\envs\\tensorflow\\lib\\socket.py\", line 705, in readinto\n",
      "    return self._sock.recv_into(b)\n",
      "  File \"c:\\Users\\sarth\\.conda\\envs\\tensorflow\\lib\\ssl.py\", line 1274, in recv_into\n",
      "    return self.read(nbytes, buffer)\n",
      "  File \"c:\\Users\\sarth\\.conda\\envs\\tensorflow\\lib\\ssl.py\", line 1130, in read\n",
      "    return self._sslobj.read(len, buffer)\n",
      "TimeoutError: The read operation timed out\n",
      "\n",
      "During handling of the above exception, another exception occurred:\n",
      "\n",
      "Traceback (most recent call last):\n",
      "  File \"c:\\Users\\sarth\\.conda\\envs\\tensorflow\\lib\\site-packages\\pip\\_internal\\cli\\base_command.py\", line 160, in exc_logging_wrapper\n",
      "    status = run_func(*args)\n",
      "  File \"c:\\Users\\sarth\\.conda\\envs\\tensorflow\\lib\\site-packages\\pip\\_internal\\cli\\req_command.py\", line 247, in wrapper\n",
      "    return func(self, options, args)\n",
      "  File \"c:\\Users\\sarth\\.conda\\envs\\tensorflow\\lib\\site-packages\\pip\\_internal\\commands\\install.py\", line 400, in run\n",
      "    requirement_set = resolver.resolve(\n",
      "  File \"c:\\Users\\sarth\\.conda\\envs\\tensorflow\\lib\\site-packages\\pip\\_internal\\resolution\\resolvelib\\resolver.py\", line 92, in resolve\n",
      "    result = self._result = resolver.resolve(\n",
      "  File \"c:\\Users\\sarth\\.conda\\envs\\tensorflow\\lib\\site-packages\\pip\\_vendor\\resolvelib\\resolvers.py\", line 481, in resolve\n",
      "    state = resolution.resolve(requirements, max_rounds=max_rounds)\n",
      "  File \"c:\\Users\\sarth\\.conda\\envs\\tensorflow\\lib\\site-packages\\pip\\_vendor\\resolvelib\\resolvers.py\", line 373, in resolve\n",
      "    failure_causes = self._attempt_to_pin_criterion(name)\n",
      "  File \"c:\\Users\\sarth\\.conda\\envs\\tensorflow\\lib\\site-packages\\pip\\_vendor\\resolvelib\\resolvers.py\", line 213, in _attempt_to_pin_criterion\n",
      "    criteria = self._get_updated_criteria(candidate)\n",
      "  File \"c:\\Users\\sarth\\.conda\\envs\\tensorflow\\lib\\site-packages\\pip\\_vendor\\resolvelib\\resolvers.py\", line 204, in _get_updated_criteria\n",
      "    self._add_to_criteria(criteria, requirement, parent=candidate)\n",
      "  File \"c:\\Users\\sarth\\.conda\\envs\\tensorflow\\lib\\site-packages\\pip\\_vendor\\resolvelib\\resolvers.py\", line 172, in _add_to_criteria\n",
      "    if not criterion.candidates:\n",
      "  File \"c:\\Users\\sarth\\.conda\\envs\\tensorflow\\lib\\site-packages\\pip\\_vendor\\resolvelib\\structs.py\", line 151, in __bool__\n",
      "    return bool(self._sequence)\n",
      "  File \"c:\\Users\\sarth\\.conda\\envs\\tensorflow\\lib\\site-packages\\pip\\_internal\\resolution\\resolvelib\\found_candidates.py\", line 155, in __bool__\n",
      "    return any(self)\n",
      "  File \"c:\\Users\\sarth\\.conda\\envs\\tensorflow\\lib\\site-packages\\pip\\_internal\\resolution\\resolvelib\\found_candidates.py\", line 143, in <genexpr>\n",
      "    return (c for c in iterator if id(c) not in self._incompatible_ids)\n",
      "  File \"c:\\Users\\sarth\\.conda\\envs\\tensorflow\\lib\\site-packages\\pip\\_internal\\resolution\\resolvelib\\found_candidates.py\", line 47, in _iter_built\n",
      "    candidate = func()\n",
      "  File \"c:\\Users\\sarth\\.conda\\envs\\tensorflow\\lib\\site-packages\\pip\\_internal\\resolution\\resolvelib\\factory.py\", line 206, in _make_candidate_from_link\n",
      "    self._link_candidate_cache[link] = LinkCandidate(\n",
      "  File \"c:\\Users\\sarth\\.conda\\envs\\tensorflow\\lib\\site-packages\\pip\\_internal\\resolution\\resolvelib\\candidates.py\", line 297, in __init__\n",
      "    super().__init__(\n",
      "  File \"c:\\Users\\sarth\\.conda\\envs\\tensorflow\\lib\\site-packages\\pip\\_internal\\resolution\\resolvelib\\candidates.py\", line 162, in __init__\n",
      "    self.dist = self._prepare()\n",
      "  File \"c:\\Users\\sarth\\.conda\\envs\\tensorflow\\lib\\site-packages\\pip\\_internal\\resolution\\resolvelib\\candidates.py\", line 231, in _prepare\n",
      "    dist = self._prepare_distribution()\n",
      "  File \"c:\\Users\\sarth\\.conda\\envs\\tensorflow\\lib\\site-packages\\pip\\_internal\\resolution\\resolvelib\\candidates.py\", line 308, in _prepare_distribution\n",
      "    return preparer.prepare_linked_requirement(self._ireq, parallel_builds=True)\n",
      "  File \"c:\\Users\\sarth\\.conda\\envs\\tensorflow\\lib\\site-packages\\pip\\_internal\\operations\\prepare.py\", line 491, in prepare_linked_requirement\n",
      "    return self._prepare_linked_requirement(req, parallel_builds)\n",
      "  File \"c:\\Users\\sarth\\.conda\\envs\\tensorflow\\lib\\site-packages\\pip\\_internal\\operations\\prepare.py\", line 536, in _prepare_linked_requirement\n",
      "    local_file = unpack_url(\n",
      "  File \"c:\\Users\\sarth\\.conda\\envs\\tensorflow\\lib\\site-packages\\pip\\_internal\\operations\\prepare.py\", line 166, in unpack_url\n",
      "    file = get_http_url(\n",
      "  File \"c:\\Users\\sarth\\.conda\\envs\\tensorflow\\lib\\site-packages\\pip\\_internal\\operations\\prepare.py\", line 107, in get_http_url\n",
      "    from_path, content_type = download(link, temp_dir.path)\n",
      "  File \"c:\\Users\\sarth\\.conda\\envs\\tensorflow\\lib\\site-packages\\pip\\_internal\\network\\download.py\", line 147, in __call__\n",
      "    for chunk in chunks:\n",
      "  File \"c:\\Users\\sarth\\.conda\\envs\\tensorflow\\lib\\site-packages\\pip\\_internal\\cli\\progress_bars.py\", line 53, in _rich_progress_bar\n",
      "    for chunk in iterable:\n",
      "  File \"c:\\Users\\sarth\\.conda\\envs\\tensorflow\\lib\\site-packages\\pip\\_internal\\network\\utils.py\", line 63, in response_chunks\n",
      "    for chunk in response.raw.stream(\n",
      "  File \"c:\\Users\\sarth\\.conda\\envs\\tensorflow\\lib\\site-packages\\pip\\_vendor\\urllib3\\response.py\", line 621, in stream\n",
      "    data = self.read(amt=amt, decode_content=decode_content)\n",
      "  File \"c:\\Users\\sarth\\.conda\\envs\\tensorflow\\lib\\site-packages\\pip\\_vendor\\urllib3\\response.py\", line 559, in read\n",
      "    with self._error_catcher():\n",
      "  File \"c:\\Users\\sarth\\.conda\\envs\\tensorflow\\lib\\contextlib.py\", line 153, in __exit__\n",
      "    self.gen.throw(typ, value, traceback)\n",
      "  File \"c:\\Users\\sarth\\.conda\\envs\\tensorflow\\lib\\site-packages\\pip\\_vendor\\urllib3\\response.py\", line 442, in _error_catcher\n",
      "    raise ReadTimeoutError(self._pool, None, \"Read timed out.\")\n",
      "pip._vendor.urllib3.exceptions.ReadTimeoutError: HTTPSConnectionPool(host='files.pythonhosted.org', port=443): Read timed out.\n"
     ]
    },
    {
     "name": "stdout",
     "output_type": "stream",
     "text": [
      "Collecting tensorflow\n",
      "  Using cached tensorflow-2.12.0-cp310-cp310-win_amd64.whl (1.9 kB)\n",
      "Collecting tensorflow-intel==2.12.0\n",
      "  Downloading tensorflow_intel-2.12.0-cp310-cp310-win_amd64.whl (272.8 MB)\n",
      "     ---------                             72.5/272.8 MB 136.8 kB/s eta 0:24:24\n"
     ]
    }
   ],
   "source": [
    "%pip install tensorflow"
   ]
  },
  {
   "cell_type": "code",
   "execution_count": 2,
   "metadata": {},
   "outputs": [
    {
     "ename": "ValueError",
     "evalue": "could not broadcast input array from shape (15,388,3) into shape (15,300,3)",
     "output_type": "error",
     "traceback": [
      "\u001b[1;31m---------------------------------------------------------------------------\u001b[0m",
      "\u001b[1;31mValueError\u001b[0m                                Traceback (most recent call last)",
      "Cell \u001b[1;32mIn[2], line 18\u001b[0m\n\u001b[0;32m     16\u001b[0m imgCrop\u001b[39m=\u001b[39m img[y\u001b[39m-\u001b[39m offset:y\u001b[39m+\u001b[39mh\u001b[39m+\u001b[39moffset, x\u001b[39m-\u001b[39moffset:x\u001b[39m+\u001b[39mw\u001b[39m+\u001b[39moffset]\n\u001b[0;32m     17\u001b[0m imgCropShape\u001b[39m=\u001b[39mimgCrop\u001b[39m.\u001b[39mshape\n\u001b[1;32m---> 18\u001b[0m imgWhite[\u001b[39m0\u001b[39;49m:imgCropShape[\u001b[39m0\u001b[39;49m], \u001b[39m0\u001b[39;49m:imgCropShape[\u001b[39m1\u001b[39;49m]] \u001b[39m=\u001b[39m imgCrop\n\u001b[0;32m     19\u001b[0m cv2\u001b[39m.\u001b[39mimshow(\u001b[39m\"\u001b[39m\u001b[39mimagecrop\u001b[39m\u001b[39m\"\u001b[39m, imgCrop)\n\u001b[0;32m     20\u001b[0m cv2\u001b[39m.\u001b[39mimshow(\u001b[39m\"\u001b[39m\u001b[39mimageWhite\u001b[39m\u001b[39m\"\u001b[39m, imgWhite)\n",
      "\u001b[1;31mValueError\u001b[0m: could not broadcast input array from shape (15,388,3) into shape (15,300,3)"
     ]
    },
    {
     "ename": "",
     "evalue": "",
     "output_type": "error",
     "traceback": [
      "\u001b[1;31mThe Kernel crashed while executing code in the the current cell or a previous cell. Please review the code in the cell(s) to identify a possible cause of the failure. Click <a href='https://aka.ms/vscodeJupyterKernelCrash'>here</a> for more info. View Jupyter <a href='command:jupyter.viewOutput'>log</a> for further details."
     ]
    }
   ],
   "source": [
    "import cv2\n",
    "import numpy as np\n",
    "import maths\n",
    "from cvzone.HandTrackingModule import HandDetector\n",
    "import time\n",
    "# cap = cv2.VideoCapture\n",
    "cap = cv2.VideoCapture(0)\n",
    "\n",
    "detector= HandDetector(maxHands=1)\n",
    "\n",
    "offset = 20 \n",
    "\n",
    "imgSize= 300\n",
    "\n",
    "folder= \"Data/A\"\n",
    "# folder= \"Data/B\"\n",
    "# folder= \"Data/C\"\n",
    "\n",
    "counter=0\n",
    "while True:\n",
    "    success, img = cap.read()\n",
    "    hands, img = detector.findHands(img)\n",
    "    if hands:\n",
    "        hand = hands[0]\n",
    "\n",
    "        x,y,w,h= hand['bbox']\n",
    "        \n",
    "        imgWhite= np.ones((imgSize, imgSize, 3), np.uint8)*255\n",
    "\n",
    "        imgCrop= img[y- offset:y+h+offset, x-offset:x+w+offset]\n",
    "        \n",
    "        imgCropShape=imgCrop.shape\n",
    "        \n",
    "        aspectRAtio=h/w\n",
    "        if aspectRatio >1:\n",
    "            k=imgSize/h\n",
    "            wCal= math.ceil(k*w)\n",
    "            imgResize = cv2.resize(imgCrop, (wCal, imgSize))\n",
    "            imgResizeShape = imgResize.shape\n",
    "            wGap=math.ceil((imgSize- wCal)/2)\n",
    "            imgWhite[:, wGap:wCal+wGap] = imgResize\n",
    "\n",
    "        else:\n",
    "            k=imgSize/w\n",
    "            wCal= math.ceil(k*h)\n",
    "            imgResize = cv2.resize(imgCrop, (imgSize, hCal))\n",
    "            imgResizeShape = imgResize.shape\n",
    "            hGap=math.ceil((imgSize- hCal)/2)\n",
    "            imgWhite[ hGap:hCal+hGap, :] = imgResize\n",
    "    \n",
    "\n",
    "\n",
    "        \n",
    "        cv2.imshow(\"imagecrop\", imgCrop)\n",
    "        \n",
    "        cv2.imshow(\"imageWhite\", imgWhite)\n",
    "    \n",
    "    cv2.imshow(\"image\",img)\n",
    "    \n",
    "    key = cv2.waitKey(1) & 0xFF\n",
    "    if key== ord(\"s\"):\n",
    "        counter += 1\n",
    "        cv2.imwrite(f'{folder}/Image_{time.time()}.jpg',imgWhite)\n",
    "        print(counter)\n",
    "\n",
    "    if key == ord(\"q\"):\n",
    "         break"
   ]
  },
  {
   "cell_type": "code",
   "execution_count": null,
   "metadata": {},
   "outputs": [],
   "source": []
  }
 ],
 "metadata": {
  "kernelspec": {
   "display_name": "tensorflow",
   "language": "python",
   "name": "python3"
  },
  "language_info": {
   "codemirror_mode": {
    "name": "ipython",
    "version": 3
   },
   "file_extension": ".py",
   "mimetype": "text/x-python",
   "name": "python",
   "nbconvert_exporter": "python",
   "pygments_lexer": "ipython3",
   "version": "3.10.8"
  },
  "orig_nbformat": 4,
  "vscode": {
   "interpreter": {
    "hash": "7c9535f37598d57666df5949ea9b0e56ad96ecf26aae602d7607c3f951eb74cd"
   }
  }
 },
 "nbformat": 4,
 "nbformat_minor": 2
}
